Workbook

Sheet Total
B2: Total | P2: 구매처 | X2: ID | AA2: PW
P3: https://www.digikey.kr/
P5: https://www.devicemart.co.kr/main/index
B6: 품명 | E6: 필요수량 | H6: 보유수량 | K6: 구매 필요 여부 | M6: 주문여부
B7: TE 3핀 커넥터 | E7: =HVBOX!L8+HVBOX!AA8+BSPD!L10 -> 4 | H7: 23 | K7: =IF(2*E7>H7, "O", "") | M7: FALSE | P7: https://www.mouser.kr/
B9: TE 2핀 커넥터 | E9: =HVBOX!L11+HVBOX!AA10+Discharge!L8 -> 12 | H9: 26 | K9: =IF(2*E9>H9, "O", "") | M9: FALSE | P9: https://www.eleparts.co.kr/main/index
B11: 960kΩ | E11: =HVBOX!L15 -> 1 | H11: 10 | K11: =IF(2*E11>H11, "O", "") | M11: FALSE
P12: 전압 분배 테이블 | V12: 주소지
B13: 40kΩ | E13: =HVBOX!L17 -> 1 | H13: 0 | K13: =IF(2*E13>H13, "O", "") -> O | M13: TRUE
P14: V_in | Q14: 16.8 | S14: =1/(Q14/Q17) -> 0.5952381 | V14: 이민성 집
B15: LM311P | E15: =HVBOX!L19+BSPD!L12 -> 12 | H15: 12 | K15: =IF(2*E15>H15, "O", "") -> O | M15: TRUE | S15: =S14/(1-S14) -> 1.4705882
P16: =IF(S15<0, "in보다 ref는 클수 없음", "") | S16: x | T16: y
B17: 50V 0.1uF | E17: =HVBOX!L21 -> 1 | H17: 20 | K17: =IF(2*E17>H17, "O", "") | M17: FALSE | P17: V_ref | Q17: 10 | S17: 4.7 | T17: =$S$15*S17 -> 6.9117647
B19: 2.4kΩ | E19: =HVBOX!L23+BSPD!L28 -> 8 | H19: 50 | K19: =IF(2*E19>H19, "O", "") | M19: FALSE
B21: SPAN0E12 | E21: =HVBOX!L25 -> 1 | H21: 5 | K21: =IF(2*E21>H21, "O", "") | M21: FALSE
B23: N채널 모스펫 | E23: =HVBOX!L27+SDC!L18+BSPD!L20 -> 10 | H23: 40 | K23: =IF(2*E23>H23, "O", "") | M23: FALSE
B25: CS1-12H | E25: =HVBOX!L29+HVBOX!AA16+SDC!L30+BSPD!L16 -> 9 | H25: 24 | K25: =IF(2*E25>H25, "O", "") | M25: FALSE | P25: NE555 비안정 | AC25: NE555 단안정
B27: 1N4004 | E27: =HVBOX!L31+HVBOX!AA20+SDC!L16+BSPD!L30 -> 21 | H27: 50 | K27: =IF(2*E27>H27, "O", "") | M27: FALSE
P28: 10 | S28: 300 | V28: 1 | Y28: =1.44/((P28+2*S28)*V28)*1000 -> 2.3606557 | AC28: 47 | AF28: 10 | AI28: =1.1*AC28*AF28/1000 -> 0.517
B29: NE555P | E29: =HVBOX!L33+HVBOX!AA26+SDC!L26+BSPD!L14 -> 6 | H29: 36 | K29: =IF(2*E29>H29, "O", "") | M29: FALSE
B31: 30kΩ | E31: =HVBOX!L35+BSPD!L40 -> 2 | H31: 0 | K31: =IF(2*E31>H31, "O", "") -> O | M31: TRUE | P31: R1 (kΩ) | S31: R2 (kΩ) | V31: C1 (uF) | Y31: Frequency (Hz) | AC31: R1 (kΩ) | AF31: C1 (uF) | AI31: Time (s)
B33: 300kΩ | E33: =HVBOX!L37 -> 1 | H33: 0 | K33: =IF(2*E33>H33, "O", "") -> O | M33: TRUE
B35: 1uF | E35: =BSPD!L36 -> 1 | H35: 50 | K35: =IF(2*E35>H35, "O", "") | M35: FALSE
B37: 80kΩ | E37: =HVBOX!L41 -> 1 | H37: 10 | K37: =IF(2*E37>H37, "O", "") | M37: FALSE
B39: 20kΩ | E39: =HVBOX!L43 -> 1 | H39: 50 | K39: =IF(2*E39>H39, "O", "") | M39: FALSE
B41: 330kΩ | E41: =HVBOX!AA12 -> 1 | H41: 50 | K41: =IF(2*E41>H41, "O", "") | M41: FALSE
B43: 10uF | E43: =HVBOX!AA14+SDC!L14+BSPD!L32 -> 13 | H43: 100 | K43: =IF(2*E43>H43, "O", "") | M43: FALSE
B45: G2RL-2(TH 3개) | E45: =HVBOX!AA18+SDC!L28+Discharge!L12 -> 3 | H45: 12 | K45: =IF(2*E45>H45, "O", "") | M45: FALSE
B47: P채널 모스펫 | E47: =HVBOX!AA22+SDC!L20+BSPD!L22 -> 8 | H47: 36 | K47: =IF(2*E47>H47, "O", "") | M47: FALSE
B49: 10kΩ | E49: =HVBOX!AA24+SDC!L22+BSPD!L26 -> 16 | H49: 50 | K49: =IF(2*E49>H49, "O", "") | M49: FALSE
B51: HS50 2.2kΩ | E51: =HVBOX!AA28+Discharge!L10 -> 2 | H51: 0 | K51: =IF(2*E51>H51, "O", "") -> O | M51: TRUE
B53: TE 10핀 커넥터 | E53: =SDC!L8 -> 5 | H53: 9 | K53: =IF(2*E53>H53, "O", "") -> O | M53: TRUE
B55: TE 8핀 커넥터 | E55: =SDC!L10+BSPD!L8 -> 2 | H55: 6 | K55: =IF(2*E55>H55, "O", "") | M55: FALSE
B57: TE 6핀 커넥터 | E57: =SDC!L12 -> 2 | H57: 9 | K57: =IF(2*E57>H57, "O", "") | M57: FALSE
B59: LM7805 | E59: =SDC!L24 -> 1 | H59: 3 | K59: =IF(2*E59>H59, "O", "") | M59: FALSE
B61: RT424F12 | E61: =SDC!L32 -> 4 | H61: 30 | K61: =IF(2*E61>H61, "O", "") | M61: FALSE
B63: 250kΩ | E63: =SDC!L34 -> 1 | H63: 20 | K63: =IF(2*E63>H63, "O", "") | M63: FALSE
B65: 330kΩ | E65: =SDC!L36 -> 1 | H65: 50 | K65: =IF(2*E65>H65, "O", "") | M65: FALSE
B67: 900kΩ(910kΩ) | E67: =BSPD!L38 -> 1 | H67: 50 | K67: =IF(2*E67>H67, "O", "") | M67: FALSE
B69: 2.2kΩ | E69: =SDC!L40 -> 1 | H69: 50 | K69: =IF(2*E69>H69, "O", "") | M69: FALSE
...

Sheet HVBOX
B2: TSAL & AVI Circuit | Q2: Pre-Charge Circuit
B6: 번호 | C6: 품명 | F6: 내용 | L6: 필요 수량 | N6: 보유 수량 | Q6: 번호 | R6: 품명 | U6: 내용 | AA6: 필요 수량 | AC6: 보유 수량
B8: 1 | C8: TE 3핀 커넥터 | F8: GLVS 전원 공급, 외부 LED연결 | L8: 2 | N8: =Total!H7 -> 23 | Q8: 1 | R8: TE 3핀 커넥터 | U8: GLVS 전원 공급 | AA8: 1 | AC8: =Total!H7 -> 23
Q10: 2 | R10: TE 2핀 커넥터 | U10: Air1, Air2, Pre-TSAL (+, -), HV+ | AA10: 4 | AC10: =Total!H9 -> 26
B11: 2 | C11: TE 2핀 커넥터 | F11: Air1,2 / Precharge릴레이 기구적 감지 | L11: 5 | N11: =Total!H9 -> 26
Q12: 3 | R12: 330kΩ | U12: 타이머용 저항 | AA12: 1 | AC12: =Total!H41 -> 50
F13: 고전압 영역 +, - / AVI +,-
Q14: 4 | R14: 10uF | U14: 노이즈 제거용 커패시터, 타이머용 커패시터 | AA14: 3 | AC14: =Total!H43 -> 100
B15: 4 | C15: 960kΩ | F15: 고전압 전압 분배용 저항 | L15: 1 | N15: =Total!H11 -> 10
Q16: 5 | R16: CS1-12H | U16: 타이머 릴레이 | AA16: 1 | AC16: =Total!H25 -> 24
B17: 5 | C17: 40kΩ | F17: 고전압 전압 분배용 저항 | L17: 1 | N17: =Total!H13 -> 0
Q18: 6 | R18: G2RL-2 | U18: 초기충전 릴레이 | AA18: 1 | AC18: =Total!H45 -> 12
B19: 6 | C19: LM311P | F19: 고전압 감지용 비교기 | L19: 2 | N19: =Total!H15 -> 12
Q20: 7 | R20: 1N4004 | U20: 릴레이 역기전력 방지 환류 다이오드 | AA20: 4 | AC20: =Total!H27 -> 50
B21: 7 | C21: 50V 0.1uF | F21: 비교기 노이즈 제거용 커패시터 | L21: 1 | N21: =Total!H17 -> 20
Q22: 8 | R22: P채널 모스펫 | U22: Air1 제어용 모스펫 | AA22: 1 | AC22: =Total!H47 -> 36
B23: 8 | C23: 2.4kΩ | F23: 옵토커플러 전류제한 저항 | L23: 3 | N23: =Total!H19 -> 50
Q24: 9 | R24: 10kΩ | U24: 단락방지 저항 | AA24: 1 | AC24: =Total!H49 -> 50
B25: 9 | C25: SPAN0E12 | F25: 절연형 DC-DC 12V 컨버터 | L25: 1 | N25: =Total!H21 -> 5
Q26: 10 | R26: NE555 | U26: Air1 여자 3.63s 딜레이용 타이머 | AA26: 1 | AC26: =Total!H29 -> 36
B27: 10 | C27: N채널 모스펫 | F27: 릴레이 제어용 N채널 모스펫, RED LED용 모스펫 | L27: 3 | N27: =Total!H23 -> 40
Q28: 11 | R28: HS50 2.2kΩ | U28: 초기충전용 저항 | AA28: 1 | AC28: =Total!H51 -> 0
B29: 11 | C29: CS1-12H | F29: 저전압용 릴레이 | L29: 2 | N29: =Total!H25 -> 24
B31: 12 | C31: 1N4004 | F31: 릴레이 역기전력 방지 환류 다이오드 | L31: 2 | N31: =Total!H27 -> 50
AC32: 1/4W 제외 수량
B33: 13 | C33: NE555P | F33: 2.28Hz용 비안정 RED LED용 타이머 | L33: 1 | N33: =Total!H29 -> 36
B35: 14 | C35: 30kΩ | F35: 타이머용 저항1 | L35: 1 | N35: =Total!H31 -> 0
B37: 15 | C37: 300kΩ | F37: 타이머용 저항2 | L37: 1 | N37: =Total!H33 -> 0
B39: 16 | C39: 1uF | F39: 타이머용 커패시터 | L39: 1 | N39: =Total!H35 -> 50
B41: 17 | C41: 80kΩ | F41: 고전압 비교용 전압 분배 저항 | L41: 1 | N41: =Total!H37 -> 10
B43: 18 | C43: 20kΩ | F43: 고전압 비교용 전압 분배 저항 | L43: 1 | N43: =Total!H39 -> 50
B48: NE555 비안정 | O48: NE555 단안정
B51: 10 | E51: 10 | H51: 1 | K51: =1.44/((B51+2*E51)*H51)*1000 -> 48 | O51: 47 | R51: 10 | U51: =1.1*O51*R51/1000 -> 0.517
B54: R1 (kΩ) | E54: R2 (kΩ) | H54: C1 (uF) | K54: Frequency (Hz) | O54: R1 (kΩ) | R54: C1 (uF) | U54: Time (s)

Sheet SDC
B2: SDC Circuit
B6: 번호 | C6: 품명 | F6: 내용 | L6: 필요 수량 | N6: 보유 수량 | R6: 1/4W 제외 수량
B8: 1 | C8: TE 10핀 커넥터 | F8: REAR, HV BOX, FRONT RTD, SDC, MASTER BOARD | L8: 5 | N8: =Total!H53 -> 9
B10: 2 | C10: TE 8핀 커넥터 | F10: BSPD | L10: 1 | N10: =Total!H55 -> 6
B12: 3 | C12: TE 6핀 커넥터 | F12: ENERGY METER, 12V POWER | L12: 2 | N12: =Total!H57 -> 9
B14: 4 | C14: 10uF | F14: 노이즈 제거용, | L14: 8 | N14: =Total!H43 -> 100
B16: 5 | C16: 1N4004 | F16: 릴레이 역기전력 방지 환류 다이오드 | L16: 14 | N16: =Total!H27 -> 50
B18: 6 | C18: N채널 모스펫 | F18: BMS1, BMS2, BSPD, RTD HVMS | L18: 4 | N18: =Total!H23 -> 40
B20: 7 | C20: P채널 모스펫 | F20: IMD, RTDS, BSPD | L20: 3 | N20: =Total!H47 -> 36
B22: 8 | C22: 10k | F22: 단락방지 저항 | L22: 6 | N22: =Total!H49 -> 50
B24: 9 | C24: LM7805 | F24: 5V 레귤레이터 | L24: 1 | N24: =Total!H59 -> 3
B26: 10 | C26: NE555P | F26: BSPD 10s, RTDS, HVMS(RTD 3.6s) | L26: 3 | N26: =Total!H29 -> 36
B28: 11 | C28: G2RL2-12DC | F28: RTD 자기유지 | L28: 1 | N28: =Total!H45 -> 12
B30: 12 | C30: CS1-12H | F30: 차단회로 5직렬 릴레이 | L30: 5 | N30: =Total!H25 -> 24
B32: 13 | C32: RT424F12 | F32: 차단회로 래칭릴레이 | L32: 4 | N32: =Total!H61 -> 30
B34: 14 | C34: 250k | F34: 타이머용 저항 | L34: 1 | N34: =Total!H63 -> 20
B36: 15 | C36: 330k | F36: 타이머용 저항 | L36: 1 | N36: =Total!H65 -> 50
B38: 16 | C38: 900k | F38: 타이머용 저항 | L38: 1 | N38: =Total!H67 -> 50
B40: 17 | C40: 2.2k | F40: 단락방지 저항 | L40: 1 | N40: =Total!H69 -> 50

Sheet BSPD
B2: BSPD Circuit
B6: 번호 | C6: 품명 | F6: 내용 | L6: 필요 수량 | N6: 보유 수량
B8: 1 | C8: TE 8핀 커넥터 | F8: bspd 8pin conn | L8: 1 | N8: =Total!H55 -> 6 | Q8: 1/4W 제외 수량
B10: 2 | C10: TE 3핀 커넥터 | F10: hall, presure senor, gnd | L10: 1 | N10: =Total!H7 -> 23 | Q10: 전압 분배 테이블
B12: 3 | C12: LM311P | F12: presure, hall sensor 비교기 | L12: 10 | N12: =Total!H15 -> 12 | Q12: V_in | R12: 5 | T12: =1/(R12/R15) -> 0.32
T13: =T12/(1-T12) -> 0.47058824
B14: 4 | C14: NE555P | F14: 타이머 소자 | L14: 1 | N14: =Total!H29 -> 36 | T14: x | U14: y
Q15: V_ref | R15: 1.6 | T15: 70 | U15: =$T$13*T15 -> 32.941176
B16: 5 | C16: CS1-12H | F16: 노말 상황 and 게이트 릴레이 | L16: 1 | N16: =Total!H25 -> 24
B18: 6 | C18: PC817 | F18: and 게이트 | L18: 5 | N18: =Total!H71 -> 50
B20: 7 | C20: N채널 모스펫 | F20: and 게이트, 안정성 증가 nmos | L20: 3 | N20: =Total!H23 -> 40
B22: 8 | C22: P채널 모스펫 | F22: bspd fault pmos | L22: 4 | N22: =Total!H47 -> 36
B24: 9 | C24: DIP SW | F24: 슬라이드 스위치 | L24: 2 | N24: =Total!H73 -> 10
B26: 10 | C26: 10kΩ | F26: pull down 저항 | L26: 9 | N26: =Total!H49 -> 50
B28: 11 | C28: 2.4k Ω | F28: 비교기 pull up 저항 | L28: 5 | N28: =Total!H19 -> 50
B30: 12 | C30: 1N4004 | F30: 릴레이 역기전력 방지 환류 다이오드 | L30: 1 | N30: =Total!H27 -> 50
B32: 13 | C32: 10uF | F32: 타이머용 커패시터 | L32: 2 | N32: =Total!H43 -> 100
B34: 14 | C34: 250Ω | F34: 전압 강하용 저항1 | L34: 1 | N34: =Total!H75 -> 50
B36: 15 | C36: 2kΩ | F36: 전압 강하용 저항2 | L36: 1 | N36: =Total!H77 -> 50
B38: 16 | C38: 3kΩ | F38: 전압 강하용 저항3 | L38: 1 | N38: =Total!H79 -> 50
B40: 17 | C40: 30k => 4.7k | F40: 전압 강하용 저항4 | L40: 1 | N40: =Total!H31 -> 0
B42: 18 | C42: 47kΩ | F42: 0.5s 딜레이용 저항 | L42: 1 | N42: =Total!H81 -> 50
B44: 19 | C44: 70k => 10k | F44: 전압 강하용 저항6 | L44: 1 | N44: =Total!H83 -> 0
B46: 20 | C46: 90kΩ | F46: 전압 강하용 저항7 | L46: 1 | N46: =Total!H85 -> 50

Sheet Discharge
B2: Discharge Circuit
B6: 번호 | C6: 품명 | F6: 내용 | L6: 필요 수량 | N6: 보유 수량
B8: 1 | C8: TE 2핀 커넥터 | L8: 3 | N8: =Total!H9 -> 26
B10: 2 | C10: HS50 2.2kΩ | F10: 방전용 저항 | L10: 1 | N10: =Total!H51 -> 0
B12: 3 | C12: G2RL2-12DC | F12: 방전 릴레이 | L12: 1 | N12: =Total!H45 -> 12
B14: 4
B16: 5
