Workbook
Name Car: 원가명세표!$K$2
Name Car: #REF!
Name CompCode: 원가명세표!$I$2
Name CompCode: #REF!
Name dd: #REF!
Name dd: #REF!
Name Process_P1: #REF!
Name Process_P1: #REF!
Name Processes: #REF!
Name Processes: #REF!
Name Uni: #REF!
Name Uni: #REF!

Sheet 종합
B2: KSAE 대학생 자작자동차대회 비용보고서(원가명세표)
B4: 엔트리 | D4: =원가명세표!I1 -> 5
B5: 학교명 | D5: =원가명세표!K1 -> 영남대학교
B6: 팀 명 | D6: =원가명세표!CompCode -> 천마DM
B7: 차량제작비 | D7: =원가명세표!Car -> 53038287
B9: 연번 | C9: 구분 | D9: 금액
B10: 1 | C10: 엔진&구동시스템 | D10: =원가명세표!K386 -> 29516404
B11: 2 | C11: 조향시스템 | D11: =원가명세표!K23 -> 1359486
B12: 3 | C12: 현가시스템 | D12: =원가명세표!K83 -> 8819776
B13: 4 | C13: 제동시스템 | D13: =원가명세표!K119 -> 1760668
B14: 5 | C14: 프레임&바디 | D14: =원가명세표!K201 -> 2492308
B15: 6 | C15: 전장시스템 | D15: =원가명세표!K551 -> 1643380
B16: 7 | C16: 휠&타이어 | D16: =원가명세표!K206 -> 6018192
B17: 8 | C17: 기타 | D17: =원가명세표!K242 -> 1428072.8
C18: 차량제작비 합계 | D18: =SUM(D10:D17) -> 53038287
B20: ** 원가명세표 시트에서 자동 계산된 결과입니다.
B21: ** 원가명세표 시트만 작성하시면 됩니다.
B23: ** 원가명세표는 팀의 현실적인 비용관리가 최우선 입니다.
B24: 1) '제품명, 구매-가공처' 항목은 다음 차량 제작 시 참고가 목적
B25: 2) 구매품, 가공품(부품-재료비, 외주 가공비)에 한해 기입 (기타 용접, 커팅, 노동비 등 제외)
B27: 3) 기존 사용 물품 또는 스폰서 물품의 경우 현재 시세가격으로 기입
B28: 4) 볼트, 너트, 밴드 등은 적용된 시스템에 기입 (중점 점검 항목)
B29: 5) 케이블타이, 절연 테이프 등은 제외
B30: ** 원가명세표 예시 참조

Sheet 원가명세표
A1: KSAE 대학생 자작자동차대회 비용보고서(원가명세표) | H1: 엔트리 | I1: 5 | J1: 학교명 | K1: 영남대학교 | M1: 기입 항목 | N1: 수정 금지
H2: 팀 명 | I2: 천마DM | J2: 차량제작비 | K2: =K552 -> 53038287
A4: 연번 | B4: 구분 | C4: Assy | E4: 제품명 | F4: 구매, 가공처 | G4: 부품, 재료비 | H4: 외주 가공비 | I4: 단가 | J4: 수량 | K4: 합계
A5: 1 | B5: 조향시스템 | C5: Steering Wheel Assy | D5: Steering Wheel | E5: Steering Wheel | F5: 동아레이저 | H5: 15000 | I5: =SUM(G5:H5) -> 15000 | J5: 1 | K5: =I5*J5 -> 15000
A6: 2 | B6: 조향시스템 | D6: Steering Wheel | E6: B-G Racing-Steering Wheel Quick Release | F6: B-G Racing | G6: 85468 | I6: =SUM(G6:H6) -> 85468 | J6: 1 | K6: =I6*J6 -> 85468
A7: 3 | B7: 조향시스템 | D7: Steering Wheel | E7: M6 나일론 록 너트 | F7: 대경볼트 | G7: 40 | I7: =SUM(G7:H7) -> 40 | J7: 4 | K7: =I7*J7 -> 160
A8: 4 | B8: 조향시스템 | D8: Steering Wheel | E8: 렌치볼트 M6-15mm | F8: 대경볼트 | G8: 50 | I8: =SUM(G8:H8) -> 50 | J8: 4 | K8: =I8*J8 -> 200
A9: 5 | B9: 조향시스템 | C9: Rack&Pinion Assy | D9: Rack&Pinion | E9: Narrco Rack & Pinion | F9: Fsaeparts | G9: 917000 | I9: =SUM(G9:H9) -> 917000 | J9: 1 | K9: =I9*J9 -> 917000
A10: 6 | B10: 조향시스템 | D10: Rack&Pinion | E10: Rack & Pinion Mount | F10: 신하정공 | G10: 50000 | I10: =SUM(G10:H10) -> 50000 | J10: 2 | K10: =I10*J10 -> 100000
A11: 7 | B11: 조향시스템 | D11: Rack&Pinion | E11: Ray Steering Column | F11: 현대 모비스 | G11: 45000 | I11: =SUM(G11:H11) -> 45000 | J11: 1 | K11: =I11*J11 -> 45000
A12: 8 | B12: 조향시스템 | D12: Rack&Pinion | E12: 랜치볼트 M6-35mm | F12: 대경볼트 | G12: 50 | I12: =SUM(G12:H12) -> 50 | J12: 12 | K12: =I12*J12 -> 600
A13: 9 | B13: 조향시스템 | D13: Rack&Pinion | E13: Rack & Pinion M6 나일론 록 너트 | F13: 대경볼트 | G13: 40 | I13: =SUM(G13:H13) -> 40 | J13: 8 | K13: =I13*J13 -> 320
A14: 10 | B14: 조향시스템 | D14: Rack&Pinion cover | E14: 레이저컷 | F14: 동아레이저 | G14: 4000 | I14: =SUM(G14:H14) -> 4000 | J14: 1 | K14: =I14*J14 -> 4000
A15: 11 | B15: 조향시스템 | D15: cover pop nut | E15: M6 팝너트 | F15: 네이버쇼핑 | G15: 100 | I15: =SUM(G15:H15) -> 100 | J15: 4 | K15: =I15*J15 -> 400
A16: 12 | B16: 조향시스템 | C16: Steering Shaft Assy | D16: Steering Shaft | E16: Steering Upper Shaft | F16: B-G Racing | H16: 42350 | I16: =SUM(G16:H16) -> 42350 | J16: 1 | K16: =I16*J16 -> 42350
A17: 13 | B17: 조향시스템 | D17: Steering Shaft | E17: Steering Lower Shaft | F17: 현대 모비스 | H17: 12500 | I17: =SUM(G17:H17) -> 12500 | J17: 1 | K17: =I17*J17 -> 12500
A18: 14 | B18: 조향시스템 | D18: Steering Shaft Housing | E18: Steering Shaft Housing | F18: 신하정공 | H18: 60000 | I18: =SUM(G18:H18) -> 60000 | J18: 1 | K18: =I18*J18 -> 60000
A19: 15 | B19: 조향시스템 | C19: Tie Rod Assy | D19: Tie Rod | E19: Tie Rod Pipe(D14) | F19: AARK 공동구매 | G19: 10000 | I19: =SUM(G19:H19) -> 10000 | J19: 1 | K19: =I19*J19 -> 10000
A20: 16 | B20: 조향시스템 | D20: Tie Rod | E20: AM-M6 | F20: 오로라베어링 | G20: 16532 | I20: =SUM(G20:H20) -> 16532 | J20: 4 | K20: =I20*J20 -> 66128
A21: 17 | B21: 조향시스템 | D21: Tie Rod | E21: 렌치볼트 M6-40mm | F21: 대경볼트 | G21: 50 | I21: =SUM(G21:H21) -> 50 | J21: 4 | K21: =I21*J21 -> 200
A22: 18 | B22: 조향시스템 | D22: Tie Rod | E22: M6 나일론 록 너트 | F22: 대경볼트 | G22: 40 | I22: =SUM(G22:H22) -> 40 | J22: 4 | K22: =I22*J22 -> 160
D23: 합계 | K23: =SUM(K5:K22) -> 1359486
A24: 1 | B24: 현가시스템 | C24: Front Stabilizer Assy | D24: Stabilizer bar | E24: Front Stabilizer Bar | F24: 신하정공 | H24: 150000 | I24: =SUM(G24:H24) -> 150000 | J24: 1 | K24: =H24*J24 -> 150000
A25: 2 | B25: 현가시스템 | D25: Stabilizer moment arm | E25: Front Stabilizer Arm | F25: 신하정공 | H25: 70000 | I25: =SUM(G25:H25) -> 70000 | J25: 2 | K25: =I25*J25 -> 140000
A26: 3 | B26: 현가시스템 | D26: bolt | E26: 렌치볼트 M8-30mm | F26: 대경볼트 | G26: 60 | I26: =SUM(G26:H26) -> 60 | J26: 2 | K26: =I26*J26 -> 120
A27: 4 | B27: 현가시스템 | E27: 렌치볼트 M6-25mm | F27: 대경볼트 | G27: 50 | I27: =SUM(G27:H27) -> 50 | J27: 6 | K27: =I27*J27 -> 300
A28: 5 | B28: 현가시스템 | D28: nut | E28: M8 나일론 록 너트 | F28: 대경볼트 | G28: 50 | I28: =SUM(G28:H28) -> 50 | J28: 2 | K28: =I28*J28 -> 100
A29: 6 | B29: 현가시스템 | E29: M6 나일론 록 너트 | F29: 대경볼트 | G29: 40 | I29: =SUM(G29:H29) -> 40 | J29: 6 | K29: =I29*J29 -> 240
A30: 7 | B30: 현가시스템 | D30: Turn Buckle | E30: POS 8mm | F30: 베어링몰 | G30: 11000 | I30: =SUM(G30:H30) -> 11000 | J30: 4 | K30: =I30*J30 -> 44000
A31: 8 | B31: 현가시스템 | D31: Stabilizer Housing Assy | E31: Front Stabilizer Bar Housing | F31: 신하정공 | H31: 40000 | I31: =SUM(G31:H31) -> 40000 | J31: 2 | K31: =I31*J31 -> 80000
A32: 9 | B32: 현가시스템 | E32: 6801ZZ Bearing | F32: 베어링몰 | G32: 4500 | I32: =SUM(G32:H32) -> 4500 | J32: 4 | K32: =I32*J32 -> 18000
A33: 10 | B33: 현가시스템 | C33: Rear Stabilizer Assy | D33: Stabilizer bar | E33: Stabilizer bar | F33: KND | H33: 40000 | I33: =SUM(G33:H33) -> 40000 | J33: 1 | K33: =I33*J33 -> 40000
A34: 11 | B34: 현가시스템 | D34: Stabilizer moment arm | E34: Stabilizer moment arm | F34: 신하정공 | H34: 60000 | I34: =SUM(G34:H34) -> 60000 | J34: 2 | K34: =I34*J34 -> 120000
A35: 12 | B35: 현가시스템 | D35: bolt | E35: 렌치볼트 M6-25mm | F35: 대경볼트 | G35: 50 | I35: =SUM(G35:H35) -> 50 | J35: 10 | K35: =I35*J35 -> 500
A36: 13 | B36: 현가시스템 | D36: nut | E36: M8 나일론 록 너트 | F36: 대경볼트 | G36: 50 | I36: =SUM(G36:H36) -> 50 | J36: 2 | K36: =I36*J36 -> 100
A37: 14 | B37: 현가시스템 | E37: M6 나일론 록 너트 | F37: 대경볼트 | G37: 40 | I37: =SUM(G37:H37) -> 40 | J37: 10 | K37: =I37*J37 -> 400
A38: 15 | B38: 현가시스템 | D38: Stabilizer Turn Buckle | E38: POS 8mm | F38: 베어링몰 | G38: 11000 | I38: =SUM(G38:H38) -> 11000 | J38: 4 | K38: =I38*J38 -> 44000
A39: 16 | B39: 현가시스템 | D39: Unit bearing | E39: 강판제 필로형 유닛 ASPP | F39: 한국미스미 | G39: 15450 | I39: =SUM(G39:H39) -> 15450 | J39: 2 | K39: =I39*J39 -> 30900
A40: 17 | B40: 현가시스템 | C40: Shock Absorber | D40: Spring | E40: Hyperco TTX25 Spring | F40: Kaz Technologeis | G40: 86887 | I40: =SUM(G40:H40) -> 86887 | J40: 4 | K40: =I40*J40 -> 347548
A41: 18 | B41: 현가시스템 | D41: Damper | E41: ohlins TTX25 MKII | F41: Ohlins.co | G41: =975000 -> 975000 | I41: =SUM(G41:H41) -> 975000 | J41: 4 | K41: =I41*J41 -> 3900000
...
